Workbook

Sheet Assumptions
B2: ECAD — Cost & Profit Model
B3: Editable assumptions — change any yellow cell and every tier recalculates automatically.
B5: Assumption | C5: Value | D5: Notes
B6: Hourly labor rate (JMD) | C6: 1250 | D6: Your working number as of Aug 2026 — raise this to see a more realistic benchmark
B7: Travel cost per job (JMD) | C7: 1500 | D7: Midpoint of your stated J$1,000–2,000 gas range
B8: USD to JMD exchange rate | C8: 158 | D8: Mid-market rate, Aug 19 2026 — update periodically

Sheet Product Costs
B2: Product Cost Per Car
B3: Blue = price you gave me. Gold = revised after cross-referencing manufacturer/user data. Green = confirmed accurate.
B5: # | C5: Product | D5: Price (JMD) | E5: Coverage (cars/uses per unit) | F5: Cost per car (JMD) | G5: Status / Notes
B6: 1 | C6: Hydro-X waterless wash | D6: 2500 | E6: 25 | F6: =IFERROR(D6/E6,0) -> 100 | G6: Validated — jambs/skirts only, matches competitor benchmark
B7: 2 | C7: Koch-Chemie RRW (rinseless) | D7: 4108 | E7: 56 | F7: =IFERROR(D7/E7,0) -> 73.357143 | G7: Label math only — unconfirmed, retest once used
B8: 3 | C8: Koch-Chemie Green Star (APC) | D8: 3948 | E8: 35 | F8: =IFERROR(D8/E8,0) -> 112.8 | G8: Revised UP from your 10-20 estimate — pro benchmark suggests 30-40+
B9: 4 | C9: Car Candy Wax Soap | D9: 5500 | E9: 64 | F9: =IFERROR(D9/E9,0) -> 85.9375 | G9: 1 gallon, 2oz/car — your own usage rate
B10: 5 | C10: Car Candy Prewash | D10: 5500 | E10: 128 | F10: =IFERROR(D10/E10,0) -> 42.96875 | G10: 1 gallon, 1oz/car
B11: 6 | C11: Car Candy Interior Soap | D11: 5500 | E11: 128 | F11: =IFERROR(D11/E11,0) -> 42.96875 | G11: 1 gallon, 1oz/car (diluted for general interior use)
B12: 7 | C12: Cerakote Paint Sealant | D12: 3111 | E12: 2.5 | F12: =IFERROR(D12/E12,0) -> 1244.4 | G12: MAJOR REVISION — verified review says 2-3 cars/bottle, not 15
B13: 8 | C13: Cerakote Plastic Restorer | D13: 2354 | E13: 15 | F13: =IFERROR(D13/E13,0) -> 156.93333 | G13: No published coverage data — your estimate stands
B14: 9 | C14: Cerakote Interior Detailer | D14: 1838 | E14: 15 | F14: =IFERROR(D14/E14,0) -> 122.53333 | G14: No published coverage data — your estimate stands
B15: 10 | C15: Cerakote Wheel Sealant | D15: 2520 | E15: 15 | F15: =IFERROR(D15/E15,0) -> 168 | G15: No published coverage data — your estimate stands
B16: 11 | C16: Cerakote Tyre Coating | D16: 2362 | E16: 15 | F16: =IFERROR(D16/E16,0) -> 157.46667 | G16: No published coverage data — your estimate stands
B17: 12 | C17: Turtle Wax Wet N Black (tyre) | D17: 2700 | E17: 10 | F17: =IFERROR(D17/E17,0) -> 270 | G17: Revised DOWN from 15-20 — field report + your own Google check
... B28: 23 | C28: UWANT B300 Pro extractor fluid | D28: 0 | E28: 1 | F28: =IFERROR(D28/E28,0) -> 0 | G28: Bundled with equipment — J$0 marginal cost until refill purchased
C30: P&S Rags to Riches Detergent (per load) | D30: 3626 | E30: 21.3 | F30: =IFERROR(D30/E30,0) -> 170.23474 | G30: Confirmed by product label: 32oz qt / 1.5oz avg dose
C31: ↳ Per car (÷3 cars per wash load) | E31: 3 | F31: =F30/E31 -> 56.744914 | G31: Confirmed — matches your original math exactly

Sheet Tier Profitability
B2: Tier-by-Tier Profitability (Sedan pricing)
B3: Every product cost pulls live from the 'Product Costs' tab. Revenue cells (blue) are editable for SUV/Pickup pricing.
B5: TIER 0 — FOUNDATION | E5: 35 min (30-40 min range)
C6: Hydro-X (jambs/skirts) | D6: ='Product Costs'!$F$6 -> 100
C7: Tyre dressing (Wet N Black) | D7: ='Product Costs'!$F$17 -> 270
C8: Glass cleaner (exterior) | D8: =AVERAGE('Product Costs'!$F$23,'Product Costs'!$F$22) -> 137.68571
C9: Towel detergent | D9: ='Product Costs'!$F$31 -> 56.744914
C10: Product cost total | D10: =SUM(D6:D9) -> 564.43063
C11: Labor (0.583 hrs × hourly rate) | D11: =0.583*Assumptions!$C$6 -> 728.75
C12: Travel | D12: =Assumptions!$C$7 -> 1500
C13: TOTAL COST | D13: =D10+D11+D12 -> 2793.1806
C15: Vehicle Class | D15: Revenue (JMD) | E15: Profit (JMD) | F15: Margin %
C16: Sedan | D16: 5500 | E16: =D16-D13 -> 2706.8194 | F16: =IFERROR(E16/D16,0) -> 0.49214898
C17: SUV | D17: 6500 | E17: =D17-D13 -> 3706.8194 | F17: =IFERROR(E17/D17,0) -> 0.5702799
C18: Pickup/Van | D18: 7500 | E18: =D18-D13 -> 4706.8194 | F18: =IFERROR(E18/D18,0) -> 0.62757592
B21: TIER 1 — REFINED | E21: 82.5 min (75-90 min range)
C22: Everything in Foundation | D22: ='Tier Profitability'!$D$10 -> 564.43063
C23: Prewash | D23: ='Product Costs'!$F$10 -> 42.96875
C24: APC dashboard/console (Green Star) | D24: ='Product Costs'!$F$8 -> 112.8
C25: Glass cleaner (interior) | D25: =AVERAGE('Product Costs'!$F$23,'Product Costs'!$F$22) -> 137.68571
C26: Wheel cleaner combo (Turtle Wax + HMH) | D26: ='Product Costs'!$F$19+'Product Costs'!$F$20 -> 267.06462
C27: Plastic restorer (Car Guys) | D27: ='Product Costs'!$F$24 -> 344.54545
C28: Tyre gel dressing | D28: ='Product Costs'!$F$17 -> 270
C29: Product cost total | D29: =SUM(D22:D28) -> 1739.4952
C30: Labor (1.375 hrs × hourly rate) | D30: =1.375*Assumptions!$C$6 -> 1718.75
C31: Travel | D31: =Assumptions!$C$7 -> 1500
C32: TOTAL COST | D32: =D29+D30+D31 -> 4958.2452
C34: Vehicle Class | D34: Revenue (JMD) | E34: Profit (JMD) | F34: Margin %
C35: Sedan | D35: 9000 | E35: =D35-D32 -> 4041.7548 | F35: =IFERROR(E35/D35,0) -> 0.44908387
C36: SUV | D36: 11000 | E36: =D36-D32 -> 6041.7548 | F36: =IFERROR(E36/D36,0) -> 0.54925044
C37: Pickup/Van | D37: 13000 | E37: =D37-D32 -> 8041.7548 | F37: =IFERROR(E37/D37,0) -> 0.61859653
B40: TIER 2 — ELEVATED | E40: 2.5 hrs (2-3 hr range)
C41: Everything in Refined | D41: ='Tier Profitability'!$D$29 -> 1739.4952
C42: Seat shampoo/extraction (UWANT fluid) | D42: ='Product Costs'!$F$28 -> 0
C43: Carpet deep clean (UWANT fluid) | D43: ='Product Costs'!$F$28 -> 0
C44: Leather clean & condition | D44: ='Product Costs'!$F$26 -> 177.75
C45: Cerakote Interior Detailer | D45: ='Product Costs'!$F$14 -> 122.53333
C46: Product cost total | D46: =SUM(D41:D45) -> 2039.7785
C47: Labor (2.5 hrs × hourly rate) | D47: =2.5*Assumptions!$C$6 -> 3125
C48: Travel | D48: =Assumptions!$C$7 -> 1500
...
